Traceback (most recent call last):
  File "/opt/hostedtoolcache/Python/3.12.11/x64/lib/python3.12/site-packages/jupyter_core/utils/__init__.py", line 154, in wrapped
    asyncio.get_running_loop()
RuntimeError: no running event loop

During handling of the above exception, another exception occurred:

Traceback (most recent call last):
  File "/opt/hostedtoolcache/Python/3.12.11/x64/lib/python3.12/site-packages/jupyter_cache/executors/utils.py", line 58, in single_nb_execution
    executenb(
  File "/opt/hostedtoolcache/Python/3.12.11/x64/lib/python3.12/site-packages/nbclient/client.py", line 1319, in execute
    return NotebookClient(nb=nb, resources=resources, km=km, **kwargs).execute()
           ^^^^^^^^^^^^^^^^^^^^^^^^^^^^^^^^^^^^^^^^^^^^^^^^^^^^^^^^^^^^^^^^^^^^^
  File "/opt/hostedtoolcache/Python/3.12.11/x64/lib/python3.12/site-packages/jupyter_core/utils/__init__.py", line 158, in wrapped
    return loop.run_until_complete(inner)
           ^^^^^^^^^^^^^^^^^^^^^^^^^^^^^^
  File "/opt/hostedtoolcache/Python/3.12.11/x64/lib/python3.12/asyncio/base_events.py", line 691, in run_until_complete
    return future.result()
           ^^^^^^^^^^^^^^^
  File "/opt/hostedtoolcache/Python/3.12.11/x64/lib/python3.12/site-packages/nbclient/client.py", line 709, in async_execute
    await self.async_execute_cell(
  File "/opt/hostedtoolcache/Python/3.12.11/x64/lib/python3.12/site-packages/nbclient/client.py", line 1062, in async_execute_cell
    await self._check_raise_for_error(cell, cell_index, exec_reply)
  File "/opt/hostedtoolcache/Python/3.12.11/x64/lib/python3.12/site-packages/nbclient/client.py", line 918, in _check_raise_for_error
    raise CellExecutionError.from_cell_and_msg(cell, exec_reply_content)
nbclient.exceptions.CellExecutionError: An error occurred while executing the following cell:
------------------
from multisim import Simulator

sims = Simulator(
    X,  # Design matrix
    effects,    # effects to simulate
    noise_std,  # Observation noise
    n_channels,  # Number of channelss
    n_subjects,  # Number of subjects
    -0.25,
    1.0,  # Start and end of epochs
    sfreq,  # Sampling frequency of the data
    ch_cov=ch_cov,  # Spatial covariance of the data
)
print(sims.summary())

# Convert to MNE epochs:
epochs = sims.export_to_mne(X=X.copy(), mapping=mapping)

# Alternatively, save to eeglab format
sims.export_to_eeglab(
    X=X.copy(),
    mapping=mapping,
    root="./data",
    fname_template="sub-{:02d}_task-sim-epo.set",
)
------------------

----- stdout -----
Subjects  : 20
Epochs    : 160
Samples   : 61
Channels  : 32
Conditions: 2 (category, attention)
----- stderr -----
/home/runner/work/meeg_simulator/meeg_simulator/multisim/simulator.py:73: SyntaxWarning: invalid escape sequence '\s'
  d' = \\frac{a}{\sigma}
------------------

[31m---------------------------------------------------------------------------[39m
[31mModuleNotFoundError[39m                       Traceback (most recent call last)
[36mFile [39m[32m~/work/meeg_simulator/meeg_simulator/multisim/simulator.py:363[39m, in [36mSimulator.export_to_mne[39m[34m(self, ch_type, X, mapping, verbose)[39m
[32m    362[39m [38;5;28;01mtry[39;00m:
[32m--> [39m[32m363[39m     [38;5;28;01mfrom[39;00m[38;5;250m [39m[34;01mmne[39;00m[38;5;250m [39m[38;5;28;01mimport[39;00m create_info, EpochsArray
[32m    364[39m [38;5;28;01mexcept[39;00m [38;5;167;01mImportError[39;00m:

[31mModuleNotFoundError[39m: No module named 'mne'

During handling of the above exception, another exception occurred:

[31mImportError[39m                               Traceback (most recent call last)
[36mCell[39m[36m [39m[32mIn[4][39m[32m, line 17[39m
[32m     14[39m [38;5;28mprint[39m(sims.summary())
[32m     16[39m [38;5;66;03m# Convert to MNE epochs:[39;00m
[32m---> [39m[32m17[39m epochs = [43msims[49m[43m.[49m[43mexport_to_mne[49m[43m([49m[43mX[49m[43m=[49m[43mX[49m[43m.[49m[43mcopy[49m[43m([49m[43m)[49m[43m,[49m[43m [49m[43mmapping[49m[43m=[49m[43mmapping[49m[43m)[49m
[32m     19[39m [38;5;66;03m# Alternatively, save to eeglab format[39;00m
[32m     20[39m sims.export_to_eeglab(
[32m     21[39m     X=X.copy(),
[32m     22[39m     mapping=mapping,
[32m     23[39m     root=[33m"[39m[33m./data[39m[33m"[39m,
[32m     24[39m     fname_template=[33m"[39m[33msub-[39m[38;5;132;01m{:02d}[39;00m[33m_task-sim-epo.set[39m[33m"[39m,
[32m     25[39m )

[36mFile [39m[32m~/work/meeg_simulator/meeg_simulator/multisim/simulator.py:365[39m, in [36mSimulator.export_to_mne[39m[34m(self, ch_type, X, mapping, verbose)[39m
[32m    363[39m     [38;5;28;01mfrom[39;00m[38;5;250m [39m[34;01mmne[39;00m[38;5;250m [39m[38;5;28;01mimport[39;00m create_info, EpochsArray
[32m    364[39m [38;5;28;01mexcept[39;00m [38;5;167;01mImportError[39;00m:
[32m--> [39m[32m365[39m     [38;5;28;01mraise[39;00m [38;5;167;01mImportError[39;00m(
[32m    366[39m         [33m"[39m[33mMNE-Python could not be imported. Use the following installation method [39m[33m"[39m
[32m    367[39m         [33m"[39m[33mappropriate for your environment:[39m[38;5;130;01m\n[39;00m[38;5;130;01m\n[39;00m[33m"[39m
[32m    368[39m         [33mf[39m[33m"[39m[33m    pip install mne[39m[38;5;130;01m\n[39;00m[33m"[39m
[32m    369[39m         [33mf[39m[33m"[39m[33m    conda install -c conda-forge mne[39m[33m"[39m
[32m    370[39m     )
[32m    371[39m [38;5;66;03m# Create events:[39;00m
[32m    372[39m events, event_id = [38;5;28mself[39m.generate_events(X, mapping)

[31mImportError[39m: MNE-Python could not be imported. Use the following installation method appropriate for your environment:

    pip install mne
    conda install -c conda-forge mne

